# Handling Errors in Python with `try...except`

## Introduction: What are Errors (Exceptions)?

When you write and run Python code, things don't always go as planned. Sometimes, the interpreter encounters a situation it doesn't know how to handle. This could be due to various reasons:

*   Trying to divide a number by zero.
*   Trying to perform an operation on incompatible data types (like adding a number to a string).
*   Trying to access a file that doesn't exist.
*   Trying to access a list item using an index that is out of bounds.

When these situations occur, Python "raises" an **exception**. An exception is an event that disrupts the normal flow of the program's execution. If an exception is not handled, the program will crash and display an error message (often called a traceback).

**Why handle exceptions?**

*   **Prevent Crashes:** Gracefully handle errors instead of letting the program terminate abruptly.
*   **User Experience:** Provide informative messages to the user instead of cryptic error codes.
*   **Robustness:** Make your program more reliable by anticipating potential problems.
*   **Resource Management:** Ensure resources like files or network connections are properly closed, even if errors occur.

## The `try...except` Block: Basic Syntax

Python provides the `try...except` statement to handle exceptions. The basic idea is:

1.  **`try`**: Put the code that *might* cause an error inside the `try` block.
2.  **`except`**: Put the code that should run *if* an error occurs inside the `except` block.

```python
# Example: Division by zero

numerator = 10
denominator = 0

try:
    # Code that might cause an error
    result = numerator / denominator
    print(f"The result is: {result}") # This line won't run if an error occurs above
except:
    # Code to run IF an error happened in the 'try' block
    print("Oops! An error occurred. Cannot divide by zero.")

print("Program continues after the try-except block.")
```

**Explanation:**

*   Python attempts to execute the code inside the `try` block (`result = numerator / denominator`).
*   Since dividing by zero is mathematically impossible, Python raises a `ZeroDivisionError` exception.
*   The normal execution within the `try` block stops immediately.
*   Python looks for an `except` block that can handle this situation.
*   The code inside the `except` block is executed (`print("Oops! ...")`).
*   The program then continues running *after* the `try...except` structure. Without `try...except`, the program would have crashed at the division step.

## Handling Specific Exceptions

The basic `except:` block catches *any* type of error. While this prevents crashes, it's often too broad. You might want to handle different errors in different ways. You can specify the type of exception you want to catch after the `except` keyword.

```python
try:
    user_input = input("Enter a number: ")
    number = int(user_input) # Potential ValueError if input is not a number
    result = 10 / number     # Potential ZeroDivisionError if input is 0
    print(f"10 divided by your number is: {result}")

except ValueError:
    print("Invalid input! Please enter a valid integer.")

except ZeroDivisionError:
    print("You cannot divide by zero!")

print("Program finished.")
```

**Explanation:**

*   If the user enters text like "hello", `int(user_input)` will raise a `ValueError`. The first `except ValueError:` block will catch it.
*   If the user enters `0`, `10 / number` will raise a `ZeroDivisionError`. The second `except ZeroDivisionError:` block will catch it.
*   If any *other* type of error occurs (less likely in this simple example), it won't be caught, and the program might still crash. This is often desirable because you want to know about unexpected errors.

## Handling Multiple Exceptions in One Block

If you want to perform the same action for several different exception types, you can group them in a tuple.

```python
try:
    user_input = input("Enter a number: ")
    number = int(user_input)
    result = 10 / number
    print(f"10 divided by your number is: {result}")

except (ValueError, ZeroDivisionError):
    print("Invalid input or division by zero occurred. Please enter a non-zero integer.")

print("Program finished.")
```

## The `else` Clause

Sometimes, you have code that should *only* run if the `try` block completed *without* raising any exceptions. You can use the optional `else` clause for this.

```python
numerator = 10
denominator = 2 # Changed to a valid number

try:
    print("Attempting division...")
    result = numerator / denominator
except ZeroDivisionError:
    print("Cannot divide by zero!")
else:
    # This block runs ONLY if the 'try' block succeeded without errors
    print(f"Division successful! Result: {result}")

print("After try-except-else.")
```

**Explanation:**

*   The code in the `try` block runs.
*   Since `denominator` is 2, no `ZeroDivisionError` occurs.
*   The `except` block is skipped.
*   The `else` block is executed because no exception was raised in the `try` block.

## The `finally` Clause

There's another optional clause: `finally`. The code inside the `finally` block *always* executes, regardless of whether an exception occurred in the `try` block or not. This is extremely useful for cleanup actions, like closing files or releasing network resources, ensuring they happen even if errors interrupt the main logic.

```python
file = None # Initialize file variable
try:
    print("Opening file...")
    file = open("my_data.txt", "r") # Try to open a file (might not exist -> FileNotFoundError)
    content = file.read()
    print("File content:", content)
    # Let's simulate another potential error
    result = 10 / 0 # ZeroDivisionError

except FileNotFoundError:
    print("Error: The file 'my_data.txt' was not found.")
except ZeroDivisionError:
    print("Error: Cannot divide by zero during processing.")
except Exception as e: # Catch any other potential errors
    print(f"An unexpected error occurred: {e}")
else:
    print("File read successfully without errors.")
finally:
    # This block ALWAYS runs
    print("Executing finally block...")
    if file: # Check if the file was successfully opened before trying to close it
        print("Closing file.")
        file.close()
    else:
        print("No file was opened.")

print("Program continues after the try-except-finally structure.")
```

**Explanation:**

*   If `my_data.txt` doesn't exist, `FileNotFoundError` is caught. The `finally` block still runs to print "Closing file." (though `file` would be `None`).
*   If the file exists but the division by zero occurs, `ZeroDivisionError` is caught. The `finally` block still runs to close the file.
*   If the file exists and no other errors occur, the `try` block completes, the `else` block runs, and the `finally` block still runs to close the file.
*   The `finally` block guarantees the cleanup code (like `file.close()`) is attempted.

## Getting Exception Information

You can get access to the actual exception object that was raised using `as`. This object often contains useful details about the error.

```python
try:
    user_input = input("Enter something that isn't a number: ")
    number = int(user_input)
except ValueError as e: # Assign the exception object to the variable 'e'
    print(f"A ValueError occurred!")
    print(f"Error details: {e}") # Print the standard error message associated with the exception
    print(f"Error type: {type(e)}")

```

Running this and entering "hello" might output:

```
A ValueError occurred!
Error details: invalid literal for int() with base 10: 'hello'
Error type: <class 'ValueError'>
```

## Raising Exceptions (`raise`)

You can also deliberately raise exceptions in your own code using the `raise` keyword. This is useful when you detect an error condition based on your program's logic.

```python
def calculate_discount(price, discount_percent):
    if not 0 <= discount_percent <= 100:
        # Raise an error if the discount is invalid
        raise ValueError("Discount percentage must be between 0 and 100.")
    if price < 0:
        raise ValueError("Price cannot be negative.")

    discount_amount = price * (discount_percent / 100)
    return price - discount_amount

try:
    final_price = calculate_discount(50, 110) # Invalid discount
    print(f"Final price: {final_price}")
except ValueError as e:
    print(f"Error calculating discount: {e}")

try:
    final_price = calculate_discount(-20, 10) # Invalid price
    print(f"Final price: {final_price}")
except ValueError as e:
    print(f"Error calculating discount: {e}")

try:
    final_price = calculate_discount(100, 15) # Valid input
    print(f"Final price: {final_price}")
except ValueError as e:
    print(f"Error calculating discount: {e}")

```

## Common Built-in Exceptions

Python has many built-in exceptions. Some you'll encounter frequently include:

*   `Exception`: The base class for most errors. Catching this is slightly better than a bare `except:`, but still quite general.
*   `AttributeError`: Trying to access an attribute or method that doesn't exist on an object.
*   `ImportError`: Failing to import a module.
*   `IndexError`: Trying to access a list/tuple element with an index that is out of range.
*   `KeyError`: Trying to access a dictionary key that doesn't exist.
*   `NameError`: Using a variable or function name that hasn't been defined.
*   `TypeError`: Performing an operation on an object of an inappropriate type.
*   `ValueError`: Performing an operation on an object with an inappropriate value (but the correct type), like `int("hello")`.
*   `ZeroDivisionError`: Dividing by zero.
*   `FileNotFoundError`: Trying to open a file that doesn't exist in read mode.
*   `OSError`: System-related errors, often related to file I/O.

## Best Practices

1.  **Be Specific:** Catch specific exceptions whenever possible, rather than using a bare `except:` or `except Exception:`. This makes your error handling more precise and avoids accidentally hiding bugs.
2.  **Don't Silence Errors:** Only catch errors you know how to handle. Let unexpected errors propagate (or catch `Exception` at a higher level and log it) so you become aware of them.
3.  **Use `finally` for Cleanup:** Ensure essential cleanup tasks (closing files, releasing locks, etc.) happen reliably using `finally`.
4.  **Use `else` for Success Code:** Place code that should only run if the `try` block succeeds in the `else` block to improve clarity.
5.  **Keep `try` Blocks Small:** Enclose only the specific lines of code that might raise an exception within the `try` block, not large chunks of unrelated code.

Exception handling is a fundamental part of writing robust and user-friendly Python programs. By understanding and using `try...except...else...finally` blocks effectively, you can make your code much more reliable.